Workbook

Sheet TABLERO DCA
B2: ₿ TABLERO DE CONTROL — ESTRATEGIA DCA EN BITCOIN
B3: Dollar Cost Averaging · Seguimiento de Cartera · Análisis de Rendimiento
B4: 💰 PRECIO ACTUAL BTC | D4: 📊 TOTAL INVERTIDO (USDT) | F4: ₿ BTC EN CARTERA | H4: 💵 VALOR ACTUAL (USD) | J4: 📈 RENDIMIENTO TOTAL | L4: 💵 GANANCIA EN USDT
B5: 110000 | D5: =IFERROR(SUM(D8:D107),0) -> 4326.566 | F5: =IFERROR(SUM(G8:G107),0) -> 0.067316537 | H5: =IFERROR(SUM(G8:G107)*B5,0) -> 7404.8191 | J5: =IFERROR((H5-D5)/D5,0) -> 0.71147718 | L5: =IFERROR(H5-D5,0) -> 3078.253
B6: ↑ Actualiza la celda B5 con el precio actual de BTC para refrescar toda la cartera automáticamente
B7: 📅 FECHA | C7: 💵 INVERSIÓN MONEDA LOCAL | D7: 💲 EQUIV. EN USDT | E7: 🔄 TASA COP→USDT | F7: ₿ PRECIO BTC AL COMPRAR | G7: ₿ BTC RECIBIDOS | H7: 💸 COMISIÓN PLATAFORMA | I7: 📊 INV. NETA ACUMULADA | J7: ₿ BTC TOTALES EN CARTERA | K7: 📉 COSTO PROMEDIO | L7: 💰 VALOR ACTUAL | M7: 🚦 SEMÁFORO RENDIMIENTO
B8: 46145 | C8: 100000 | D8: =C8/E8 -> 27.777778 | E8: 3600 | F8: 77000 | G8: =IFERROR(IF(D8="","",((D8-H8)/F8)),"") -> 0.00036075036 | I8: =IFERROR(IF(D8="","",SUM($D$8:D8)),"") -> 27.777778 | J8: =IFERROR(IF(G8="","",SUM($G$8:G8)),"") -> 0.00036075036 | K8: =IFERROR(IF(J8="","",I8/J8),"") -> 77000 | L8: =IFERROR(IF(J8="","",J8*$B$5),"") -> 39.68254 | M8: =IFERROR(IF(I8="","",IF((L8-I8)/I8>0.3,"🟢 TAKE PROFIT +"&TEXT((L8-I8)/I8,"0.0%")&" — VENDE PARCIAL",IF((L8-I8)/I8<-0.1,"🟡 "&TEXT((L8-I8)/I8,"0.0%")&" — ZONA DCA ACUMULA","🔵 "&TEXT((L8-I8)/I8,"0.0%")&" — HOLDING MANTÉN"))),"") -> 🟢 TAKE PROFIT +42.9% — VENDE PARCIAL
B9: 46146 | C9: 10000000 | D9: =C9/E9 -> 2631.5789 | E9: 3800 | F9: 65000 | G9: =IFERROR(IF(D9="","",((D9-H9)/F9)),"") -> 0.04048583 | I9: =IFERROR(IF(D9="","",SUM($D$8:D9)),"") -> 2659.3567 | J9: =IFERROR(IF(G9="","",SUM($G$8:G9)),"") -> 0.04084658 | K9: =IFERROR(IF(J9="","",I9/J9),"") -> 65105.982 | L9: =IFERROR(IF(J9="","",J9*$B$5),"") -> 4493.1238 | M9: =IFERROR(IF(I9="","",IF((L9-I9)/I9>0.3,"🟢 TAKE PROFIT +"&TEXT((L9-I9)/I9,"0.0%")&" — VENDE PARCIAL",IF((L9-I9)/I9<-0.1,"🟡 "&TEXT((L9-I9)/I9,"0.0%")&" — ZONA DCA ACUMULA","🔵 "&TEXT((L9-I9)/I9,"0.0%")&" — HOLDING MANTÉN"))),"") -> 🟢 TAKE PROFIT +69.0% — VENDE PARCIAL
B10: 46147 | C10: 1000000 | D10: =C10/E10 -> 270.27027 | E10: 3700 | F10: 60000 | G10: =IFERROR(IF(D10="","",((D10-H10)/F10)),"") -> 0.0045045045 | I10: =IFERROR(IF(D10="","",SUM($D$8:D10)),"") -> 2929.627 | J10: =IFERROR(IF(G10="","",SUM($G$8:G10)),"") -> 0.045351085 | K10: =IFERROR(IF(J10="","",I10/J10),"") -> 64598.829 | L10: =IFERROR(IF(J10="","",J10*$B$5),"") -> 4988.6193 | M10: =IFERROR(IF(I10="","",IF((L10-I10)/I10>0.3,"🟢 TAKE PROFIT +"&TEXT((L10-I10)/I10,"0.0%")&" — VENDE PARCIAL",IF((L10-I10)/I10<-0.1,"🟡 "&TEXT((L10-I10)/I10,"0.0%")&" — ZONA DCA ACUMULA","🔵 "&TEXT((L10-I10)/I10,"0.0%")&" — HOLDING MANTÉN"))),"") -> 🟢 TAKE PROFIT +70.3% — VENDE PARCIAL
B11: 46148 | C11: 500000 | D11: =C11/E11 -> 128.20513 | E11: 3900 | F11: 62000 | G11: =IFERROR(IF(D11="","",((D11-H11)/F11)),"") -> 0.0020678246 | I11: =IFERROR(IF(D11="","",SUM($D$8:D11)),"") -> 3057.8321 | J11: =IFERROR(IF(G11="","",SUM($G$8:G11)),"") -> 0.047418909 | K11: =IFERROR(IF(J11="","",I11/J11),"") -> 64485.501 | L11: =IFERROR(IF(J11="","",J11*$B$5),"") -> 5216.08 | M11: =IFERROR(IF(I11="","",IF((L11-I11)/I11>0.3,"🟢 TAKE PROFIT +"&TEXT((L11-I11)/I11,"0.0%")&" — VENDE PARCIAL",IF((L11-I11)/I11<-0.1,"🟡 "&TEXT((L11-I11)/I11,"0.0%")&" — ZONA DCA ACUMULA","🔵 "&TEXT((L11-I11)/I11,"0.0%")&" — HOLDING MANTÉN"))),"") -> 🟢 TAKE PROFIT +70.6% — VENDE PARCIAL
B12: 46149 | C12: 540000 | D12: =C12/E12 -> 158.82353 | E12: 3400 | F12: 58000 | G12: =IFERROR(IF(D12="","",((D12-H12)/F12)),"") -> 0.0027383367 | I12: =IFERROR(IF(D12="","",SUM($D$8:D12)),"") -> 3216.6557 | J12: =IFERROR(IF(G12="","",SUM($G$8:G12)),"") -> 0.050157246 | K12: =IFERROR(IF(J12="","",I12/J12),"") -> 64131.425 | L12: =IFERROR(IF(J12="","",J12*$B$5),"") -> 5517.2971 | M12: =IFERROR(IF(I12="","",IF((L12-I12)/I12>0.3,"🟢 TAKE PROFIT +"&TEXT((L12-I12)/I12,"0.0%")&" — VENDE PARCIAL",IF((L12-I12)/I12<-0.1,"🟡 "&TEXT((L12-I12)/I12,"0.0%")&" — ZONA DCA ACUMULA","🔵 "&TEXT((L12-I12)/I12,"0.0%")&" — HOLDING MANTÉN"))),"") -> 🟢 TAKE PROFIT +71.5% — VENDE PARCIAL
B13: 46150 | C13: 1450000 | D13: =C13/E13 -> 386.66667 | E13: 3750 | F13: 55000 | G13: =IFERROR(IF(D13="","",((D13-H13)/F13)),"") -> 0.007030303 | I13: =IFERROR(IF(D13="","",SUM($D$8:D13)),"") -> 3603.3223 | J13: =IFERROR(IF(G13="","",SUM($G$8:G13)),"") -> 0.057187549 | K13: =IFERROR(IF(J13="","",I13/J13),"") -> 63008.861 | L13: =IFERROR(IF(J13="","",J13*$B$5),"") -> 6290.6304 | M13: =IFERROR(IF(I13="","",IF((L13-I13)/I13>0.3,"🟢 TAKE PROFIT +"&TEXT((L13-I13)/I13,"0.0%")&" — VENDE PARCIAL",IF((L13-I13)/I13<-0.1,"🟡 "&TEXT((L13-I13)/I13,"0.0%")&" — ZONA DCA ACUMULA","🔵 "&TEXT((L13-I13)/I13,"0.0%")&" — HOLDING MANTÉN"))),"") -> 🟢 TAKE PROFIT +74.6% — VENDE PARCIAL
B14: 46151 | C14: 200000 | D14: =C14/E14 -> 54.794521 | E14: 3650 | F14: 50000 | G14: =IFERROR(IF(D14="","",((D14-H14)/F14)),"") -> 0.0010958904 | I14: =IFERROR(IF(D14="","",SUM($D$8:D14)),"") -> 3658.1168 | J14: =IFERROR(IF(G14="","",SUM($G$8:G14)),"") -> 0.05828344 | K14: =IFERROR(IF(J14="","",I14/J14),"") -> 62764.258 | L14: =IFERROR(IF(J14="","",J14*$B$5),"") -> 6411.1784 | M14: =IFERROR(IF(I14="","",IF((L14-I14)/I14>0.3,"🟢 TAKE PROFIT +"&TEXT((L14-I14)/I14,"0.0%")&" — VENDE PARCIAL",IF((L14-I14)/I14<-0.1,"🟡 "&TEXT((L14-I14)/I14,"0.0%")&" — ZONA DCA ACUMULA","🔵 "&TEXT((L14-I14)/I14,"0.0%")&" — HOLDING MANTÉN"))),"") -> 🟢 TAKE PROFIT +75.3% — VENDE PARCIAL
B15: 46152 | C15: 2500000 | D15: =C15/E15 -> 668.4492 | E15: 3740 | F15: 74000 | G15: =IFERROR(IF(D15="","",((D15-H15)/F15)),"") -> 0.0090330973 | I15: =IFERROR(IF(D15="","",SUM($D$8:D15)),"") -> 4326.566 | J15: =IFERROR(IF(G15="","",SUM($G$8:G15)),"") -> 0.067316537 | K15: =IFERROR(IF(J15="","",I15/J15),"") -> 64271.964 | L15: =IFERROR(IF(J15="","",J15*$B$5),"") -> 7404.8191 | M15: =IFERROR(IF(I15="","",IF((L15-I15)/I15>0.3,"🟢 TAKE PROFIT +"&TEXT((L15-I15)/I15,"0.0%")&" — VENDE PARCIAL",IF((L15-I15)/I15<-0.1,"🟡 "&TEXT((L15-I15)/I15,"0.0%")&" — ZONA DCA ACUMULA","🔵 "&TEXT((L15-I15)/I15,"0.0%")&" — HOLDING MANTÉN"))),"") -> 🟢 TAKE PROFIT +71.1% — VENDE PARCIAL
G16: =IFERROR(IF(D16="","",((D16-H16)/F16)),"") | I16: =IFERROR(IF(D16="","",SUM($D$8:D16)),"") | J16: =IFERROR(IF(G16="","",SUM($G$8:G16)),"") | K16: =IFERROR(IF(J16="","",I16/J16),"") | L16: =IFERROR(IF(J16="","",J16*$B$5),"") | M16: =IFERROR(IF(I16="","",IF((L16-I16)/I16>0.3,"🟢 TAKE PROFIT +"&TEXT((L16-I16)/I16,"0.0%")&" — VENDE PARCIAL",IF((L16-I16)/I16<-0.1,"🟡 "&TEXT((L16-I16)/I16,"0.0%")&" — ZONA DCA ACUMULA","🔵 "&TEXT((L16-I16)/I16,"0.0%")&" — HOLDING MANTÉN"))),"")
G17: =IFERROR(IF(D17="","",((D17-H17)/F17)),"") | I17: =IFERROR(IF(D17="","",SUM($D$8:D17)),"") | J17: =IFERROR(IF(G17="","",SUM($G$8:G17)),"") | K17: =IFERROR(IF(J17="","",I17/J17),"") | L17: =IFERROR(IF(J17="","",J17*$B$5),"") | M17: =IFERROR(IF(I17="","",IF((L17-I17)/I17>0.3,"🟢 TAKE PROFIT +"&TEXT((L17-I17)/I17,"0.0%")&" — VENDE PARCIAL",IF((L17-I17)/I17<-0.1,"🟡 "&TEXT((L17-I17)/I17,"0.0%")&" — ZONA DCA ACUMULA","🔵 "&TEXT((L17-I17)/I17,"0.0%")&" — HOLDING MANTÉN"))),"")
G18: =IFERROR(IF(D18="","",((D18-H18)/F18)),"") | I18: =IFERROR(IF(D18="","",SUM($D$8:D18)),"") | J18: =IFERROR(IF(G18="","",SUM($G$8:G18)),"") | K18: =IFERROR(IF(J18="","",I18/J18),"") | L18: =IFERROR(IF(J18="","",J18*$B$5),"") | M18: =IFERROR(IF(I18="","",IF((L18-I18)/I18>0.3,"🟢 TAKE PROFIT +"&TEXT((L18-I18)/I18,"0.0%")&" — VENDE PARCIAL",IF((L18-I18)/I18<-0.1,"🟡 "&TEXT((L18-I18)/I18,"0.0%")&" — ZONA DCA ACUMULA","🔵 "&TEXT((L18-I18)/I18,"0.0%")&" — HOLDING MANTÉN"))),"")
G19: =IFERROR(IF(D19="","",((D19-H19)/F19)),"") | I19: =IFERROR(IF(D19="","",SUM($D$8:D19)),"") | J19: =IFERROR(IF(G19="","",SUM($G$8:G19)),"") | K19: =IFERROR(IF(J19="","",I19/J19),"") | L19: =IFERROR(IF(J19="","",J19*$B$5),"") | M19: =IFERROR(IF(I19="","",IF((L19-I19)/I19>0.3,"🟢 TAKE PROFIT +"&TEXT((L19-I19)/I19,"0.0%")&" — VENDE PARCIAL",IF((L19-I19)/I19<-0.1,"🟡 "&TEXT((L19-I19)/I19,"0.0%")&" — ZONA DCA ACUMULA","🔵 "&TEXT((L19-I19)/I19,"0.0%")&" — HOLDING MANTÉN"))),"")
G20: =IFERROR(IF(D20="","",((D20-H20)/F20)),"") | I20: =IFERROR(IF(D20="","",SUM($D$8:D20)),"") | J20: =IFERROR(IF(G20="","",SUM($G$8:G20)),"") | K20: =IFERROR(IF(J20="","",I20/J20),"") | L20: =IFERROR(IF(J20="","",J20*$B$5),"") | M20: =IFERROR(IF(I20="","",IF((L20-I20)/I20>0.3,"🟢 TAKE PROFIT +"&TEXT((L20-I20)/I20,"0.0%")&" — VENDE PARCIAL",IF((L20-I20)/I20<-0.1,"🟡 "&TEXT((L20-I20)/I20,"0.0%")&" — ZONA DCA ACUMULA","🔵 "&TEXT((L20-I20)/I20,"0.0%")&" — HOLDING MANTÉN"))),"")
G21: =IFERROR(IF(D21="","",((D21-H21)/F21)),"") | I21: =IFERROR(IF(D21="","",SUM($D$8:D21)),"") | J21: =IFERROR(IF(G21="","",SUM($G$8:G21)),"") | K21: =IFERROR(IF(J21="","",I21/J21),"") | L21: =IFERROR(IF(J21="","",J21*$B$5),"") | M21: =IFERROR(IF(I21="","",IF((L21-I21)/I21>0.3,"🟢 TAKE PROFIT +"&TEXT((L21-I21)/I21,"0.0%")&" — VENDE PARCIAL",IF((L21-I21)/I21<-0.1,"🟡 "&TEXT((L21-I21)/I21,"0.0%")&" — ZONA DCA ACUMULA","🔵 "&TEXT((L21-I21)/I21,"0.0%")&" — HOLDING MANTÉN"))),"")
G22: =IFERROR(IF(D22="","",((D22-H22)/F22)),"") | I22: =IFERROR(IF(D22="","",SUM($D$8:D22)),"") | J22: =IFERROR(IF(G22="","",SUM($G$8:G22)),"") | K22: =IFERROR(IF(J22="","",I22/J22),"") | L22: =IFERROR(IF(J22="","",J22*$B$5),"") | M22: =IFERROR(IF(I22="","",IF((L22-I22)/I22>0.3,"🟢 TAKE PROFIT +"&TEXT((L22-I22)/I22,"0.0%")&" — VENDE PARCIAL",IF((L22-I22)/I22<-0.1,"🟡 "&TEXT((L22-I22)/I22,"0.0%")&" — ZONA DCA ACUMULA","🔵 "&TEXT((L22-I22)/I22,"0.0%")&" — HOLDING MANTÉN"))),"")
G23: =IFERROR(IF(D23="","",((D23-H23)/F23)),"") | I23: =IFERROR(IF(D23="","",SUM($D$8:D23)),"") | J23: =IFERROR(IF(G23="","",SUM($G$8:G23)),"") | K23: =IFERROR(IF(J23="","",I23/J23),"") | L23: =IFERROR(IF(J23="","",J23*$B$5),"") | M23: =IFERROR(IF(I23="","",IF((L23-I23)/I23>0.3,"🟢 TAKE PROFIT +"&TEXT((L23-I23)/I23,"0.0%")&" — VENDE PARCIAL",IF((L23-I23)/I23<-0.1,"🟡 "&TEXT((L23-I23)/I23,"0.0%")&" — ZONA DCA ACUMULA","🔵 "&TEXT((L23-I23)/I23,"0.0%")&" — HOLDING MANTÉN"))),"")
G24: =IFERROR(IF(D24="","",((D24-H24)/F24)),"") | I24: =IFERROR(IF(D24="","",SUM($D$8:D24)),"") | J24: =IFERROR(IF(G24="","",SUM($G$8:G24)),"") | K24: =IFERROR(IF(J24="","",I24/J24),"") | L24: =IFERROR(IF(J24="","",J24*$B$5),"") | M24: =IFERROR(IF(I24="","",IF((L24-I24)/I24>0.3,"🟢 TAKE PROFIT +"&TEXT((L24-I24)/I24,"0.0%")&" — VENDE PARCIAL",IF((L24-I24)/I24<-0.1,"🟡 "&TEXT((L24-I24)/I24,"0.0%")&" — ZONA DCA ACUMULA","🔵 "&TEXT((L24-I24)/I24,"0.0%")&" — HOLDING MANTÉN"))),"")
G25: =IFERROR(IF(D25="","",((D25-H25)/F25)),"") | I25: =IFERROR(IF(D25="","",SUM($D$8:D25)),"") | J25: =IFERROR(IF(G25="","",SUM($G$8:G25)),"") | K25: =IFERROR(IF(J25="","",I25/J25),"") | L25: =IFERROR(IF(J25="","",J25*$B$5),"") | M25: =IFERROR(IF(I25="","",IF((L25-I25)/I25>0.3,"🟢 TAKE PROFIT +"&TEXT((L25-I25)/I25,"0.0%")&" — VENDE PARCIAL",IF((L25-I25)/I25<-0.1,"🟡 "&TEXT((L25-I25)/I25,"0.0%")&" — ZONA DCA ACUMULA","🔵 "&TEXT((L25-I25)/I25,"0.0%")&" — HOLDING MANTÉN"))),"")
G26: =IFERROR(IF(D26="","",((D26-H26)/F26)),"") | I26: =IFERROR(IF(D26="","",SUM($D$8:D26)),"") | J26: =IFERROR(IF(G26="","",SUM($G$8:G26)),"") | K26: =IFERROR(IF(J26="","",I26/J26),"") | L26: =IFERROR(IF(J26="","",J26*$B$5),"") | M26: =IFERROR(IF(I26="","",IF((L26-I26)/I26>0.3,"🟢 TAKE PROFIT +"&TEXT((L26-I26)/I26,"0.0%")&" — VENDE PARCIAL",IF((L26-I26)/I26<-0.1,"🟡 "&TEXT((L26-I26)/I26,"0.0%")&" — ZONA DCA ACUMULA","🔵 "&TEXT((L26-I26)/I26,"0.0%")&" — HOLDING MANTÉN"))),"")
G27: =IFERROR(IF(D27="","",((D27-H27)/F27)),"") | I27: =IFERROR(IF(D27="","",SUM($D$8:D27)),"") | J27: =IFERROR(IF(G27="","",SUM($G$8:G27)),"") | K27: =IFERROR(IF(J27="","",I27/J27),"") | L27: =IFERROR(IF(J27="","",J27*$B$5),"") | M27: =IFERROR(IF(I27="","",IF((L27-I27)/I27>0.3,"🟢 TAKE PROFIT +"&TEXT((L27-I27)/I27,"0.0%")&" — VENDE PARCIAL",IF((L27-I27)/I27<-0.1,"🟡 "&TEXT((L27-I27)/I27,"0.0%")&" — ZONA DCA ACUMULA","🔵 "&TEXT((L27-I27)/I27,"0.0%")&" — HOLDING MANTÉN"))),"")
... G30: =IFERROR(IF(D30="","",((D30-H30)/F30)),"") | I30: =IFERROR(IF(D30="","",SUM($D$8:D30)),"") | J30: =IFERROR(IF(G30="","",SUM($G$8:G30)),"") | K30: =IFERROR(IF(J30="","",I30/J30),"") | L30: =IFERROR(IF(J30="","",J30*$B$5),"") | M30: =IFERROR(IF(I30="","",IF((L30-I30)/I30>0.3,"🟢 TAKE PROFIT +"&TEXT((L30-I30)/I30,"0.0%")&" — VENDE PARCIAL",IF((L30-I30)/I30<-0.1,"🟡 "&TEXT((L30-I30)/I30,"0.0%")&" — ZONA DCA ACUMULA","🔵 "&TEXT((L30-I30)/I30,"0.0%")&" — HOLDING MANTÉN"))),"")
D31: =IFERROR(IF(C31="","",IF(E31="",C31,C31/E31)),"") | G31: =IFERROR(IF(D31="","",((D31-H31)/F31)),"") | I31: =IFERROR(IF(D31="","",SUM($D$8:D31)),"") | J31: =IFERROR(IF(G31="","",SUM($G$8:G31)),"") | K31: =IFERROR(IF(J31="","",I31/J31),"") | L31: =IFERROR(IF(J31="","",J31*$B$5),"") | M31: =IFERROR(IF(I31="","",IF((L31-I31)/I31>0.3,"🟢 TAKE PROFIT +"&TEXT((L31-I31)/I31,"0.0%")&" — VENDE PARCIAL",IF((L31-I31)/I31<-0.1,"🟡 "&TEXT((L31-I31)/I31,"0.0%")&" — ZONA DCA ACUMULA","🔵 "&TEXT((L31-I31)/I31,"0.0%")&" — HOLDING MANTÉN"))),"")
D32: =IFERROR(IF(C32="","",IF(E32="",C32,C32/E32)),"") | G32: =IFERROR(IF(D32="","",((D32-H32)/F32)),"") | I32: =IFERROR(IF(D32="","",SUM($D$8:D32)),"") | J32: =IFERROR(IF(G32="","",SUM($G$8:G32)),"") | K32: =IFERROR(IF(J32="","",I32/J32),"") | L32: =IFERROR(IF(J32="","",J32*$B$5),"") | M32: =IFERROR(IF(I32="","",IF((L32-I32)/I32>0.3,"🟢 TAKE PROFIT +"&TEXT((L32-I32)/I32,"0.0%")&" — VENDE PARCIAL",IF((L32-I32)/I32<-0.1,"🟡 "&TEXT((L32-I32)/I32,"0.0%")&" — ZONA DCA ACUMULA","🔵 "&TEXT((L32-I32)/I32,"0.0%")&" — HOLDING MANTÉN"))),"")
D33: =IFERROR(IF(C33="","",IF(E33="",C33,C33/E33)),"") | G33: =IFERROR(IF(D33="","",((D33-H33)/F33)),"") | I33: =IFERROR(IF(D33="","",SUM($D$8:D33)),"") | J33: =IFERROR(IF(G33="","",SUM($G$8:G33)),"") | K33: =IFERROR(IF(J33="","",I33/J33),"") | L33: =IFERROR(IF(J33="","",J33*$B$5),"") | M33: =IFERROR(IF(I33="","",IF((L33-I33)/I33>0.3,"🟢 TAKE PROFIT +"&TEXT((L33-I33)/I33,"0.0%")&" — VENDE PARCIAL",IF((L33-I33)/I33<-0.1,"🟡 "&TEXT((L33-I33)/I33,"0.0%")&" — ZONA DCA ACUMULA","🔵 "&TEXT((L33-I33)/I33,"0.0%")&" — HOLDING MANTÉN"))),"")
D34: =IFERROR(IF(C34="","",IF(E34="",C34,C34/E34)),"") | G34: =IFERROR(IF(D34="","",((D34-H34)/F34)),"") | I34: =IFERROR(IF(D34="","",SUM($D$8:D34)),"") | J34: =IFERROR(IF(G34="","",SUM($G$8:G34)),"") | K34: =IFERROR(IF(J34="","",I34/J34),"") | L34: =IFERROR(IF(J34="","",J34*$B$5),"") | M34: =IFERROR(IF(I34="","",IF((L34-I34)/I34>0.3,"🟢 TAKE PROFIT +"&TEXT((L34-I34)/I34,"0.0%")&" — VENDE PARCIAL",IF((L34-I34)/I34<-0.1,"🟡 "&TEXT((L34-I34)/I34,"0.0%")&" — ZONA DCA ACUMULA","🔵 "&TEXT((L34-I34)/I34,"0.0%")&" — HOLDING MANTÉN"))),"")
D35: =IFERROR(IF(C35="","",IF(E35="",C35,C35/E35)),"") | G35: =IFERROR(IF(D35="","",((D35-H35)/F35)),"") | I35: =IFERROR(IF(D35="","",SUM($D$8:D35)),"") | J35: =IFERROR(IF(G35="","",SUM($G$8:G35)),"") | K35: =IFERROR(IF(J35="","",I35/J35),"") | L35: =IFERROR(IF(J35="","",J35*$B$5),"") | M35: =IFERROR(IF(I35="","",IF((L35-I35)/I35>0.3,"🟢 TAKE PROFIT +"&TEXT((L35-I35)/I35,"0.0%")&" — VENDE PARCIAL",IF((L35-I35)/I35<-0.1,"🟡 "&TEXT((L35-I35)/I35,"0.0%")&" — ZONA DCA ACUMULA","🔵 "&TEXT((L35-I35)/I35,"0.0%")&" — HOLDING MANTÉN"))),"")
D36: =IFERROR(IF(C36="","",IF(E36="",C36,C36/E36)),"") | G36: =IFERROR(IF(D36="","",((D36-H36)/F36)),"") | I36: =IFERROR(IF(D36="","",SUM($D$8:D36)),"") | J36: =IFERROR(IF(G36="","",SUM($G$8:G36)),"") | K36: =IFERROR(IF(J36="","",I36/J36),"") | L36: =IFERROR(IF(J36="","",J36*$B$5),"") | M36: =IFERROR(IF(I36="","",IF((L36-I36)/I36>0.3,"🟢 TAKE PROFIT +"&TEXT((L36-I36)/I36,"0.0%")&" — VENDE PARCIAL",IF((L36-I36)/I36<-0.1,"🟡 "&TEXT((L36-I36)/I36,"0.0%")&" — ZONA DCA ACUMULA","🔵 "&TEXT((L36-I36)/I36,"0.0%")&" — HOLDING MANTÉN"))),"")
D37: =IFERROR(IF(C37="","",IF(E37="",C37,C37/E37)),"") | G37: =IFERROR(IF(D37="","",((D37-H37)/F37)),"") | I37: =IFERROR(IF(D37="","",SUM($D$8:D37)),"") | J37: =IFERROR(IF(G37="","",SUM($G$8:G37)),"") | K37: =IFERROR(IF(J37="","",I37/J37),"") | L37: =IFERROR(IF(J37="","",J37*$B$5),"") | M37: =IFERROR(IF(I37="","",IF((L37-I37)/I37>0.3,"🟢 TAKE PROFIT +"&TEXT((L37-I37)/I37,"0.0%")&" — VENDE PARCIAL",IF((L37-I37)/I37<-0.1,"🟡 "&TEXT((L37-I37)/I37,"0.0%")&" — ZONA DCA ACUMULA","🔵 "&TEXT((L37-I37)/I37,"0.0%")&" — HOLDING MANTÉN"))),"")
D38: =IFERROR(IF(C38="","",IF(E38="",C38,C38/E38)),"") | G38: =IFERROR(IF(D38="","",((D38-H38)/F38)),"") | I38: =IFERROR(IF(D38="","",SUM($D$8:D38)),"") | J38: =IFERROR(IF(G38="","",SUM($G$8:G38)),"") | K38: =IFERROR(IF(J38="","",I38/J38),"") | L38: =IFERROR(IF(J38="","",J38*$B$5),"") | M38: =IFERROR(IF(I38="","",IF((L38-I38)/I38>0.3,"🟢 TAKE PROFIT +"&TEXT((L38-I38)/I38,"0.0%")&" — VENDE PARCIAL",IF((L38-I38)/I38<-0.1,"🟡 "&TEXT((L38-I38)/I38,"0.0%")&" — ZONA DCA ACUMULA","🔵 "&TEXT((L38-I38)/I38,"0.0%")&" — HOLDING MANTÉN"))),"")
D39: =IFERROR(IF(C39="","",IF(E39="",C39,C39/E39)),"") | G39: =IFERROR(IF(D39="","",((D39-H39)/F39)),"") | I39: =IFERROR(IF(D39="","",SUM($D$8:D39)),"") | J39: =IFERROR(IF(G39="","",SUM($G$8:G39)),"") | K39: =IFERROR(IF(J39="","",I39/J39),"") | L39: =IFERROR(IF(J39="","",J39*$B$5),"") | M39: =IFERROR(IF(I39="","",IF((L39-I39)/I39>0.3,"🟢 TAKE PROFIT +"&TEXT((L39-I39)/I39,"0.0%")&" — VENDE PARCIAL",IF((L39-I39)/I39<-0.1,"🟡 "&TEXT((L39-I39)/I39,"0.0%")&" — ZONA DCA ACUMULA","🔵 "&TEXT((L39-I39)/I39,"0.0%")&" — HOLDING MANTÉN"))),"")
D40: =IFERROR(IF(C40="","",IF(E40="",C40,C40/E40)),"") | G40: =IFERROR(IF(D40="","",((D40-H40)/F40)),"") | I40: =IFERROR(IF(D40="","",SUM($D$8:D40)),"") | J40: =IFERROR(IF(G40="","",SUM($G$8:G40)),"") | K40: =IFERROR(IF(J40="","",I40/J40),"") | L40: =IFERROR(IF(J40="","",J40*$B$5),"") | M40: =IFERROR(IF(I40="","",IF((L40-I40)/I40>0.3,"🟢 TAKE PROFIT +"&TEXT((L40-I40)/I40,"0.0%")&" — VENDE PARCIAL",IF((L40-I40)/I40<-0.1,"🟡 "&TEXT((L40-I40)/I40,"0.0%")&" — ZONA DCA ACUMULA","🔵 "&TEXT((L40-I40)/I40,"0.0%")&" — HOLDING MANTÉN"))),"")
D41: =IFERROR(IF(C41="","",IF(E41="",C41,C41/E41)),"") | G41: =IFERROR(IF(D41="","",((D41-H41)/F41)),"") | I41: =IFERROR(IF(D41="","",SUM($D$8:D41)),"") | J41: =IFERROR(IF(G41="","",SUM($G$8:G41)),"") | K41: =IFERROR(IF(J41="","",I41/J41),"") | L41: =IFERROR(IF(J41="","",J41*$B$5),"") | M41: =IFERROR(IF(I41="","",IF((L41-I41)/I41>0.3,"🟢 TAKE PROFIT +"&TEXT((L41-I41)/I41,"0.0%")&" — VENDE PARCIAL",IF((L41-I41)/I41<-0.1,"🟡 "&TEXT((L41-I41)/I41,"0.0%")&" — ZONA DCA ACUMULA","🔵 "&TEXT((L41-I41)/I41,"0.0%")&" — HOLDING MANTÉN"))),"")
D42: =IFERROR(IF(C42="","",IF(E42="",C42,C42/E42)),"") | G42: =IFERROR(IF(D42="","",((D42-H42)/F42)),"") | I42: =IFERROR(IF(D42="","",SUM($D$8:D42)),"") | J42: =IFERROR(IF(G42="","",SUM($G$8:G42)),"") | K42: =IFERROR(IF(J42="","",I42/J42),"") | L42: =IFERROR(IF(J42="","",J42*$B$5),"") | M42: =IFERROR(IF(I42="","",IF((L42-I42)/I42>0.3,"🟢 TAKE PROFIT +"&TEXT((L42-I42)/I42,"0.0%")&" — VENDE PARCIAL",IF((L42-I42)/I42<-0.1,"🟡 "&TEXT((L42-I42)/I42,"0.0%")&" — ZONA DCA ACUMULA","🔵 "&TEXT((L42-I42)/I42,"0.0%")&" — HOLDING MANTÉN"))),"")
... D107: =IFERROR(IF(C107="","",IF(E107="",C107,C107/E107)),"") | G107: =IFERROR(IF(D107="","",((D107-H107)/F107)),"") | I107: =IFERROR(IF(D107="","",SUM($D$8:D107)),"") | J107: =IFERROR(IF(G107="","",SUM($G$8:G107)),"") | K107: =IFERROR(IF(J107="","",I107/J107),"") | L107: =IFERROR(IF(J107="","",J107*$B$5),"") | M107: =IFERROR(IF(I107="","",IF((L107-I107)/I107>0.3,"🟢 TAKE PROFIT +"&TEXT((L107-I107)/I107,"0.0%")&" — VENDE PARCIAL",IF((L107-I107)/I107<-0.1,"🟡 "&TEXT((L107-I107)/I107,"0.0%")&" — ZONA DCA ACUMULA","🔵 "&TEXT((L107-I107)/I107,"0.0%")&" — HOLDING MANTÉN"))),"")
...

Sheet RESUMEN FISCAL
B2: 📋 RESUMEN FISCAL ANUAL — BLINDAJE TRIBUTARIO BTC
B3: Resumen por año para facilitar declaración de activos digitales (Colombia: DIAN / Internacional)
B5: 📅 AÑO | C5: 💵 TOTAL INVERTIDO | D5: ₿ BTC ADQUIRIDOS | E5: 💸 COMISIONES | F5: # OPERACIONES | G5: ₿ BTC VENDIDOS | H5: 💵 INGRESOS VENTAS | I5: 💰 GANANCIA NETA AÑO | J5: 💵 GANANCIA NO REALIZADA (USDT) | K5: 📈 ROI %
B6: 2023 | C6: =IFERROR(SUMPRODUCT((YEAR('TABLERO DCA'!$B$8:$B$107)=2023)*N('TABLERO DCA'!$D$8:$D$107)),0) -> 0 | D6: =IFERROR(SUMPRODUCT((YEAR('TABLERO DCA'!$B$8:$B$107)=2023)*N('TABLERO DCA'!$G$8:$G$107)),0) -> 0 | E6: =IFERROR(SUMPRODUCT((YEAR('TABLERO DCA'!$B$8:$B$107)=2023)*N('TABLERO DCA'!$H$8:$H$107)),0) -> 0 | F6: =IFERROR(COUNTIF('TABLERO DCA'!$B$8:$B$107,">="&DATE(2023,1,1))-COUNTIF('TABLERO DCA'!$B$8:$B$107,">="&DATE(2024,1,1)),0) -> 0 | G6: =IFERROR(SUMPRODUCT((YEAR('REGISTRO VENTAS'!$B$8:$B$107)=2023)*('REGISTRO VENTAS'!$D$8:$D$107)),0) -> 0 | H6: =IFERROR(SUMPRODUCT((YEAR('REGISTRO VENTAS'!$B$8:$B$107)=2023)*('REGISTRO VENTAS'!$F$8:$F$107)),0) -> 0 | I6: =IFERROR(SUMPRODUCT((YEAR('REGISTRO VENTAS'!$B$8:$B$107)=2023)*('REGISTRO VENTAS'!$J$8:$J$107)),0) -> 0 | J6: =IFERROR(IF(C6=0,0,D6*'TABLERO DCA'!$B$5 - C6),0) -> 0 | K6: =IFERROR(IF(C6=0,0,J6/C6),0) -> 0
B7: 2024 | C7: =IFERROR(SUMPRODUCT((YEAR('TABLERO DCA'!$B$8:$B$107)=2024)*N('TABLERO DCA'!$D$8:$D$107)),0) -> 0 | D7: =IFERROR(SUMPRODUCT((YEAR('TABLERO DCA'!$B$8:$B$107)=2024)*N('TABLERO DCA'!$G$8:$G$107)),0) -> 0 | E7: =IFERROR(SUMPRODUCT((YEAR('TABLERO DCA'!$B$8:$B$107)=2024)*N('TABLERO DCA'!$H$8:$H$107)),0) -> 0 | F7: =IFERROR(COUNTIF('TABLERO DCA'!$B$8:$B$107,">="&DATE(2024,1,1))-COUNTIF('TABLERO DCA'!$B$8:$B$107,">="&DATE(2025,1,1)),0) -> 0 | G7: =IFERROR(SUMPRODUCT((YEAR('REGISTRO VENTAS'!$B$8:$B$107)=2024)*('REGISTRO VENTAS'!$D$8:$D$107)),0) -> 0 | H7: =IFERROR(SUMPRODUCT((YEAR('REGISTRO VENTAS'!$B$8:$B$107)=2024)*('REGISTRO VENTAS'!$F$8:$F$107)),0) -> 0 | I7: =IFERROR(SUMPRODUCT((YEAR('REGISTRO VENTAS'!$B$8:$B$107)=2024)*('REGISTRO VENTAS'!$J$8:$J$107)),0) -> 0 | J7: =IFERROR(IF(C7=0,0,D7*'TABLERO DCA'!$B$5 - C7),0) -> 0 | K7: =IFERROR(IF(C7=0,0,J7/C7),0) -> 0
B8: 2025 | C8: =IFERROR(SUMPRODUCT((YEAR('TABLERO DCA'!$B$8:$B$107)=2025)*N('TABLERO DCA'!$D$8:$D$107)),0) -> 0 | D8: =IFERROR(SUMPRODUCT((YEAR('TABLERO DCA'!$B$8:$B$107)=2025)*N('TABLERO DCA'!$G$8:$G$107)),0) -> 0 | E8: =IFERROR(SUMPRODUCT((YEAR('TABLERO DCA'!$B$8:$B$107)=2025)*N('TABLERO DCA'!$H$8:$H$107)),0) -> 0 | F8: =IFERROR(COUNTIF('TABLERO DCA'!$B$8:$B$107,">="&DATE(2025,1,1))-COUNTIF('TABLERO DCA'!$B$8:$B$107,">="&DATE(2026,1,1)),0) -> 0 | G8: =IFERROR(SUMPRODUCT((YEAR('REGISTRO VENTAS'!$B$8:$B$107)=2025)*('REGISTRO VENTAS'!$D$8:$D$107)),0) -> 0 | H8: =IFERROR(SUMPRODUCT((YEAR('REGISTRO VENTAS'!$B$8:$B$107)=2025)*('REGISTRO VENTAS'!$F$8:$F$107)),0) -> 0 | I8: =IFERROR(SUMPRODUCT((YEAR('REGISTRO VENTAS'!$B$8:$B$107)=2025)*('REGISTRO VENTAS'!$J$8:$J$107)),0) -> 0 | J8: =IFERROR(IF(C8=0,0,D8*'TABLERO DCA'!$B$5 - C8),0) -> 0 | K8: =IFERROR(IF(C8=0,0,J8/C8),0) -> 0
B9: 2026 | C9: =IFERROR(SUMPRODUCT((YEAR('TABLERO DCA'!$B$8:$B$107)=2026)*N('TABLERO DCA'!$D$8:$D$107)),0) -> 4326.566 | D9: =IFERROR(SUMPRODUCT((YEAR('TABLERO DCA'!$B$8:$B$107)=2026)*N('TABLERO DCA'!$G$8:$G$107)),0) -> 0.067316537 | E9: =IFERROR(SUMPRODUCT((YEAR('TABLERO DCA'!$B$8:$B$107)=2026)*N('TABLERO DCA'!$H$8:$H$107)),0) -> 0 | F9: =IFERROR(COUNTIF('TABLERO DCA'!$B$8:$B$107,">="&DATE(2026,1,1))-COUNTIF('TABLERO DCA'!$B$8:$B$107,">="&DATE(2027,1,1)),0) -> 8 | G9: =IFERROR(SUMPRODUCT((YEAR('REGISTRO VENTAS'!$B$8:$B$107)=2026)*('REGISTRO VENTAS'!$D$8:$D$107)),0) -> 0 | H9: =IFERROR(SUMPRODUCT((YEAR('REGISTRO VENTAS'!$B$8:$B$107)=2026)*('REGISTRO VENTAS'!$F$8:$F$107)),0) -> 0 | I9: =IFERROR(SUMPRODUCT((YEAR('REGISTRO VENTAS'!$B$8:$B$107)=2026)*('REGISTRO VENTAS'!$J$8:$J$107)),0) -> 0 | J9: =IFERROR(IF(C9=0,0,D9*'TABLERO DCA'!$B$5 - C9),0) -> 3078.253 | K9: =IFERROR(IF(C9=0,0,J9/C9),0) -> 0.71147718
B10: 2027 | C10: =IFERROR(SUMPRODUCT((YEAR('TABLERO DCA'!$B$8:$B$107)=2027)*N('TABLERO DCA'!$D$8:$D$107)),0) -> 0 | D10: =IFERROR(SUMPRODUCT((YEAR('TABLERO DCA'!$B$8:$B$107)=2027)*N('TABLERO DCA'!$G$8:$G$107)),0) -> 0 | E10: =IFERROR(SUMPRODUCT((YEAR('TABLERO DCA'!$B$8:$B$107)=2027)*N('TABLERO DCA'!$H$8:$H$107)),0) -> 0 | F10: =IFERROR(COUNTIF('TABLERO DCA'!$B$8:$B$107,">="&DATE(2027,1,1))-COUNTIF('TABLERO DCA'!$B$8:$B$107,">="&DATE(2028,1,1)),0) -> 0 | G10: =IFERROR(SUMPRODUCT((YEAR('REGISTRO VENTAS'!$B$8:$B$107)=2027)*('REGISTRO VENTAS'!$D$8:$D$107)),0) -> 0 | H10: =IFERROR(SUMPRODUCT((YEAR('REGISTRO VENTAS'!$B$8:$B$107)=2027)*('REGISTRO VENTAS'!$F$8:$F$107)),0) -> 0 | I10: =IFERROR(SUMPRODUCT((YEAR('REGISTRO VENTAS'!$B$8:$B$107)=2027)*('REGISTRO VENTAS'!$J$8:$J$107)),0) -> 0 | J10: =IFERROR(IF(C10=0,0,D10*'TABLERO DCA'!$B$5 - C10),0) -> 0 | K10: =IFERROR(IF(C10=0,0,J10/C10),0) -> 0
B11: 2028 | C11: =IFERROR(SUMPRODUCT((YEAR('TABLERO DCA'!$B$8:$B$107)=2028)*N('TABLERO DCA'!$D$8:$D$107)),0) -> 0 | D11: =IFERROR(SUMPRODUCT((YEAR('TABLERO DCA'!$B$8:$B$107)=2028)*N('TABLERO DCA'!$G$8:$G$107)),0) -> 0 | E11: =IFERROR(SUMPRODUCT((YEAR('TABLERO DCA'!$B$8:$B$107)=2028)*N('TABLERO DCA'!$H$8:$H$107)),0) -> 0 | F11: =IFERROR(COUNTIF('TABLERO DCA'!$B$8:$B$107,">="&DATE(2028,1,1))-COUNTIF('TABLERO DCA'!$B$8:$B$107,">="&DATE(2029,1,1)),0) -> 0 | G11: =IFERROR(SUMPRODUCT((YEAR('REGISTRO VENTAS'!$B$8:$B$107)=2028)*('REGISTRO VENTAS'!$D$8:$D$107)),0) -> 0 | H11: =IFERROR(SUMPRODUCT((YEAR('REGISTRO VENTAS'!$B$8:$B$107)=2028)*('REGISTRO VENTAS'!$F$8:$F$107)),0) -> 0 | I11: =IFERROR(SUMPRODUCT((YEAR('REGISTRO VENTAS'!$B$8:$B$107)=2028)*('REGISTRO VENTAS'!$J$8:$J$107)),0) -> 0 | J11: =IFERROR(IF(C11=0,0,D11*'TABLERO DCA'!$B$5 - C11),0) -> 0 | K11: =IFERROR(IF(C11=0,0,J11/C11),0) -> 0
B12: 2029 | C12: =IFERROR(SUMPRODUCT((YEAR('TABLERO DCA'!$B$8:$B$107)=2029)*N('TABLERO DCA'!$D$8:$D$107)),0) -> 0 | D12: =IFERROR(SUMPRODUCT((YEAR('TABLERO DCA'!$B$8:$B$107)=2029)*N('TABLERO DCA'!$G$8:$G$107)),0) -> 0 | E12: =IFERROR(SUMPRODUCT((YEAR('TABLERO DCA'!$B$8:$B$107)=2029)*N('TABLERO DCA'!$H$8:$H$107)),0) -> 0 | F12: =IFERROR(COUNTIF('TABLERO DCA'!$B$8:$B$107,">="&DATE(2029,1,1))-COUNTIF('TABLERO DCA'!$B$8:$B$107,">="&DATE(2030,1,1)),0) -> 0 | G12: =IFERROR(SUMPRODUCT((YEAR('REGISTRO VENTAS'!$B$8:$B$107)=2029)*('REGISTRO VENTAS'!$D$8:$D$107)),0) -> 0 | H12: =IFERROR(SUMPRODUCT((YEAR('REGISTRO VENTAS'!$B$8:$B$107)=2029)*('REGISTRO VENTAS'!$F$8:$F$107)),0) -> 0 | I12: =IFERROR(SUMPRODUCT((YEAR('REGISTRO VENTAS'!$B$8:$B$107)=2029)*('REGISTRO VENTAS'!$J$8:$J$107)),0) -> 0 | J12: =IFERROR(IF(C12=0,0,D12*'TABLERO DCA'!$B$5 - C12),0) -> 0 | K12: =IFERROR(IF(C12=0,0,J12/C12),0) -> 0
B13: 2030 | C13: =IFERROR(SUMPRODUCT((YEAR('TABLERO DCA'!$B$8:$B$107)=2030)*N('TABLERO DCA'!$D$8:$D$107)),0) -> 0 | D13: =IFERROR(SUMPRODUCT((YEAR('TABLERO DCA'!$B$8:$B$107)=2030)*N('TABLERO DCA'!$G$8:$G$107)),0) -> 0 | E13: =IFERROR(SUMPRODUCT((YEAR('TABLERO DCA'!$B$8:$B$107)=2030)*N('TABLERO DCA'!$H$8:$H$107)),0) -> 0 | F13: =IFERROR(COUNTIF('TABLERO DCA'!$B$8:$B$107,">="&DATE(2030,1,1))-COUNTIF('TABLERO DCA'!$B$8:$B$107,">="&DATE(2031,1,1)),0) -> 0 | G13: =IFERROR(SUMPRODUCT((YEAR('REGISTRO VENTAS'!$B$8:$B$107)=2030)*('REGISTRO VENTAS'!$D$8:$D$107)),0) -> 0 | H13: =IFERROR(SUMPRODUCT((YEAR('REGISTRO VENTAS'!$B$8:$B$107)=2030)*('REGISTRO VENTAS'!$F$8:$F$107)),0) -> 0 | I13: =IFERROR(SUMPRODUCT((YEAR('REGISTRO VENTAS'!$B$8:$B$107)=2030)*('REGISTRO VENTAS'!$J$8:$J$107)),0) -> 0 | J13: =IFERROR(IF(C13=0,0,D13*'TABLERO DCA'!$B$5 - C13),0) -> 0 | K13: =IFERROR(IF(C13=0,0,J13/C13),0) -> 0
B14: ▶ TOTAL | C14: =SUM(C6:C13) -> 4326.566 | D14: =SUM(D6:D13) -> 0.067316537 | E14: =SUM(E6:E13) -> 0 | F14: =SUM(F6:F13) -> 8 | G14: =SUM(G6:G13) -> 0 | H14: =SUM(H6:H13) -> 0 | I14: =SUM(I6:I13) -> 0 | J14: =SUM(J6:J13) -> 3078.253 | K14: =IFERROR(IF(C14=0,0,J14/C14),0) -> 0.71147718
B16: 💡 Tip: Comparte este resumen con tu contador. En Colombia, los activos digitales se declaran como activos en el exterior ante la DIAN.

Sheet GUIA DE USO
B2: 📖 GUÍA PASO A PASO — CÓMO USAR EL TABLERO DCA
B4: 🟧 PASO 1 — ACTUALIZAR EL PRECIO ACTUAL
B5: Precio Actual BTC | C5: Escribe el precio actual de BTC en esta celda (ej: 65000). Todas las columnas de 'Valor Actual' y 'Rendimiento' se actualizan solas. Actualiza cada vez que quieras revisar tu cartera.
B6: 🟦 PASO 2 — REGISTRAR CADA COMPRA (Columnas en AZUL)
B7: Fecha | C7: Escribe la fecha de la compra. Formato: DD/MM/AAAA. Ejemplo: 15/03/2024.
B8: Inversión COP/USD | C8: Cuánto dinero invertiste en total (incluyendo comisión). Ejemplo: 200.000 COP.
B9: Precio BTC al comprar | C9: El precio del BTC en el momento exacto de tu compra. Cópialo de Binance, Buda, etc.
B10: Comisión | C10: La comisión cobrada por la plataforma. Si no hay, escribe 0.
B11: 🟩 COLUMNAS AUTOMÁTICAS (¡No tocar! — Son fórmulas)
B12: BTC Recibidos | C12: Fórmula: (Inversión − Comisión) ÷ Precio BTC. Resultado en 8 decimales (satoshis).
B13: Inv. Neta Acumulada | C13: Suma creciente de todo lo invertido. Te dice cuánto dinero real llevas puesto.
B14: BTC Totales en Cartera | C14: Suma creciente de todos tus BTC. Tu patrimonio en BTC.
B15: Costo Promedio | C15: Tu precio promedio ponderado de compra. Es el indicador más importante del DCA.
B16: Valor Actual de Cartera | C16: BTC Totales × Precio Actual (celda B5). Se actualiza cuando cambias B5.
B17: Semáforo de Rendimiento | C17: Se colorea automáticamente según tu ganancia o pérdida:
B18: 🟢 TAKE PROFIT | C18: Tu ganancia supera el +30%. El precio actual está muy por encima de tu costo promedio. Considera tomar ganancias parciales.
B19: 🟡 ZONA DCA | C19: Estás en pérdida mayor al -10%. El mercado está bajo. ¡Oportunidad de acumular más BTC a menor precio!
B20: 🔵 HOLDING | C20: Rendimiento entre -10% y +30%. Mantén tu estrategia. El DCA está funcionando.
B21: 📋 PESTAÑA RESUMEN FISCAL
B22: Resumen Fiscal Anual | C22: Muestra el total invertido, BTC adquiridos y comisiones por año. Ideal para entregar a tu contador o para la declaración de activos ante la DIAN en Colombia.
B23: 💡 CONSEJOS DCA PARA PRINCIPIANTES
B24: Compra periódica | C24: Compra BTC cada semana, quincena o mes. La clave es la constancia, no el monto.
B25: No mires el precio diario | C25: El DCA funciona a largo plazo. Revisa tu tablero máximo 1 vez por semana.
B26: Dónde comprar en Colombia | C26: Buda.com, Bitso, Binance P2P. Siempre registra la comisión exacta.
B27: Custodia de tus BTC | C27: Para montos grandes, considera moverlos a una billetera fría (hardware wallet).

Sheet REGISTRO VENTAS
B2: 📤 REGISTRO DE VENTAS — HISTORIAL DE TAKE PROFIT
B3: Registra cada venta para calcular tu ganancia realizada y controlar tu posición neta
B4: ₿ BTC VENDIDOS TOTAL | D4: 💵 INGRESOS TOTALES (USD) | F4: 💰 GANANCIA REALIZADA | H4: 📊 ROI PROMEDIO POR VENTA | J4: ₿ BTC AÚN EN CARTERA
B5: =IFERROR(SUM(D8:D107),0) -> 0 | D5: =IFERROR(SUM(F8:F107),0) -> 0 | F5: =IFERROR(SUM(J8:J107),0) -> 0 | H5: =IFERROR(AVERAGE(K8:K107),0) -> 0 | J5: =IFERROR(SUM('TABLERO DCA'!G8:G107)-SUM(D8:D107),0) -> 0.067316537
B6: ↑ Registra cada venta aquí. El campo 'Ganancia' se calcula automáticamente usando tu Costo Promedio del Tablero DCA
B7: 📅 FECHA VENTA | C7: 🔢 # ORDEN / PLATAFORMA | D7: ₿ BTC VENDIDOS | E7: ₿ PRECIO BTC AL VENDER | F7: 💵 TOTAL RECIBIDO USD | G7: 💸 COMISIÓN VENTA | H7: 📉 COSTO BASE (Precio Promedio DCA) | I7: 💰 GANANCIA BRUTA USD | J7: 💰 GANANCIA NETA USD | K7: 📈 ROI ESTA VENTA
H8: {=IFERROR(IF(D8="","",INDEX('TABLERO DCA'!$K$8:$K$107,MATCH(9.99E+307,'TABLERO DCA'!$K$8:$K$107,1))),"")} | I8: =IFERROR(IF(D8="","",(E8-H8)*D8),"") | J8: =IFERROR(IF(I8="","",I8-G8),"") | K8: =IFERROR(IF(J8="","",J8/(H8*D8)),"")
F9: =IFERROR(IF(D9="","",D9*E9-G9),"") | H9: {=IFERROR(IF(D9="","",INDEX('TABLERO DCA'!$K$8:$K$107,MATCH(9.99E+307,'TABLERO DCA'!$K$8:$K$107,1))),"")} | I9: =IFERROR(IF(D9="","",(E9-H9)*D9),"") | J9: =IFERROR(IF(I9="","",I9-G9),"") | K9: =IFERROR(IF(J9="","",J9/(H9*D9)),"")
F10: =IFERROR(IF(D10="","",D10*E10-G10),"") | H10: {=IFERROR(IF(D10="","",INDEX('TABLERO DCA'!$K$8:$K$107,MATCH(9.99E+307,'TABLERO DCA'!$K$8:$K$107,1))),"")} | I10: =IFERROR(IF(D10="","",(E10-H10)*D10),"") | J10: =IFERROR(IF(I10="","",I10-G10),"") | K10: =IFERROR(IF(J10="","",J10/(H10*D10)),"")
F11: =IFERROR(IF(D11="","",D11*E11-G11),"") | H11: {=IFERROR(IF(D11="","",INDEX('TABLERO DCA'!$K$8:$K$107,MATCH(9.99E+307,'TABLERO DCA'!$K$8:$K$107,1))),"")} | I11: =IFERROR(IF(D11="","",(E11-H11)*D11),"") | J11: =IFERROR(IF(I11="","",I11-G11),"") | K11: =IFERROR(IF(J11="","",J11/(H11*D11)),"")
F12: =IFERROR(IF(D12="","",D12*E12-G12),"") | H12: {=IFERROR(IF(D12="","",INDEX('TABLERO DCA'!$K$8:$K$107,MATCH(9.99E+307,'TABLERO DCA'!$K$8:$K$107,1))),"")} | I12: =IFERROR(IF(D12="","",(E12-H12)*D12),"") | J12: =IFERROR(IF(I12="","",I12-G12),"") | K12: =IFERROR(IF(J12="","",J12/(H12*D12)),"")
F13: =IFERROR(IF(D13="","",D13*E13-G13),"") | H13: {=IFERROR(IF(D13="","",INDEX('TABLERO DCA'!$K$8:$K$107,MATCH(9.99E+307,'TABLERO DCA'!$K$8:$K$107,1))),"")} | I13: =IFERROR(IF(D13="","",(E13-H13)*D13),"") | J13: =IFERROR(IF(I13="","",I13-G13),"") | K13: =IFERROR(IF(J13="","",J13/(H13*D13)),"")
F14: =IFERROR(IF(D14="","",D14*E14-G14),"") | H14: {=IFERROR(IF(D14="","",INDEX('TABLERO DCA'!$K$8:$K$107,MATCH(9.99E+307,'TABLERO DCA'!$K$8:$K$107,1))),"")} | I14: =IFERROR(IF(D14="","",(E14-H14)*D14),"") | J14: =IFERROR(IF(I14="","",I14-G14),"") | K14: =IFERROR(IF(J14="","",J14/(H14*D14)),"")
F15: =IFERROR(IF(D15="","",D15*E15-G15),"") | H15: {=IFERROR(IF(D15="","",INDEX('TABLERO DCA'!$K$8:$K$107,MATCH(9.99E+307,'TABLERO DCA'!$K$8:$K$107,1))),"")} | I15: =IFERROR(IF(D15="","",(E15-H15)*D15),"") | J15: =IFERROR(IF(I15="","",I15-G15),"") | K15: =IFERROR(IF(J15="","",J15/(H15*D15)),"")
F16: =IFERROR(IF(D16="","",D16*E16-G16),"") | H16: {=IFERROR(IF(D16="","",INDEX('TABLERO DCA'!$K$8:$K$107,MATCH(9.99E+307,'TABLERO DCA'!$K$8:$K$107,1))),"")} | I16: =IFERROR(IF(D16="","",(E16-H16)*D16),"") | J16: =IFERROR(IF(I16="","",I16-G16),"") | K16: =IFERROR(IF(J16="","",J16/(H16*D16)),"")
F17: =IFERROR(IF(D17="","",D17*E17-G17),"") | H17: {=IFERROR(IF(D17="","",INDEX('TABLERO DCA'!$K$8:$K$107,MATCH(9.99E+307,'TABLERO DCA'!$K$8:$K$107,1))),"")} | I17: =IFERROR(IF(D17="","",(E17-H17)*D17),"") | J17: =IFERROR(IF(I17="","",I17-G17),"") | K17: =IFERROR(IF(J17="","",J17/(H17*D17)),"")
F18: =IFERROR(IF(D18="","",D18*E18-G18),"") | H18: {=IFERROR(IF(D18="","",INDEX('TABLERO DCA'!$K$8:$K$107,MATCH(9.99E+307,'TABLERO DCA'!$K$8:$K$107,1))),"")} | I18: =IFERROR(IF(D18="","",(E18-H18)*D18),"") | J18: =IFERROR(IF(I18="","",I18-G18),"") | K18: =IFERROR(IF(J18="","",J18/(H18*D18)),"")
F19: =IFERROR(IF(D19="","",D19*E19-G19),"") | H19: {=IFERROR(IF(D19="","",INDEX('TABLERO DCA'!$K$8:$K$107,MATCH(9.99E+307,'TABLERO DCA'!$K$8:$K$107,1))),"")} | I19: =IFERROR(IF(D19="","",(E19-H19)*D19),"") | J19: =IFERROR(IF(I19="","",I19-G19),"") | K19: =IFERROR(IF(J19="","",J19/(H19*D19)),"")
F20: =IFERROR(IF(D20="","",D20*E20-G20),"") | H20: {=IFERROR(IF(D20="","",INDEX('TABLERO DCA'!$K$8:$K$107,MATCH(9.99E+307,'TABLERO DCA'!$K$8:$K$107,1))),"")} | I20: =IFERROR(IF(D20="","",(E20-H20)*D20),"") | J20: =IFERROR(IF(I20="","",I20-G20),"") | K20: =IFERROR(IF(J20="","",J20/(H20*D20)),"")
... F107: =IFERROR(IF(D107="","",D107*E107-G107),"") | H107: {=IFERROR(IF(D107="","",INDEX('TABLERO DCA'!$K$8:$K$107,MATCH(9.99E+307,'TABLERO DCA'!$K$8:$K$107,1))),"")} | I107: =IFERROR(IF(D107="","",(E107-H107)*D107),"") | J107: =IFERROR(IF(I107="","",I107-G107),"") | K107: =IFERROR(IF(J107="","",J107/(H107*D107)),"")
B109: 💡 El 'Costo Base' se toma automáticamente del costo promedio actual en tu Tablero DCA. Registra las ventas cronológicamente para mayor precisión.
